<?xml version="1.0" ?>
<!-- Generated using onshape-to-robot -->
<!-- Onshape https://cad.onshape.com/documents/2139d6249ad18a0629ecd155/w/44c8e5f7c4f912e4893cb001/e/da73c3b1a87fd35b10ae5fe0 -->
<robot name="EDULITE-A3">
  <!-- Link l1_urdf_urdf_asm -->
  <link name="l1_urdf_urdf_asm">
    <inertial>
      <origin xyz="-2.68984e-10 1.48294e-05 -0.0220571" rpy="0 0 0"/>
      <mass value="0.465144"/>
      <inertia ixx="0.00032748" ixy="-1.33894e-08" ixz="-1.85358e-12" iyy="0.000321793" iyz="-2.46949e-07" izz="0.000362426"/>
    </inertial>
    <!-- Part part_10 -->
    <visual>
      <origin xyz="0 0 -4.33681e-18" rpy="0 -0 0"/>
      <geometry>
        <mesh filename="package://edulite_a3_description/meshes/part_10.stl"/>
      </geometry>
      <material name="part_10_material">
        <color rgba="0.372549 0.654902 0.239216 1"/>
      </material>
    </visual>
    <collision>
      <origin xyz="0 0 -4.33681e-18" rpy="0 -0 0"/>
      <geometry>
        <mesh filename="package://edulite_a3_description/meshes/part_10.stl"/>
      </geometry>
    </collision>
    <!-- Part rs00_l1 -->
    <visual>
      <origin xyz="0 0 0" rpy="0 -0 0"/>
      <geometry>
        <mesh filename="package://edulite_a3_description/meshes/rs00_l1.stl"/>
      </geometry>
      <material name="rs00_l1_material">
        <color rgba="0.972549 0.529412 0.00392157 1"/>
      </material>
    </visual>
    <collision>
      <origin xyz="0 0 0" rpy="0 -0 0"/>
      <geometry>
        <mesh filename="package://edulite_a3_description/meshes/rs00_l1.stl"/>
      </geometry>
    </collision>
  </link>
  <!-- Link l1_link_urdf_asm -->
  <link name="l1_link_urdf_asm">
    <inertial>
      <origin xyz="-0.00202103 -0.00162495 0.0394318" rpy="0 0 0"/>
      <mass value="0.146738"/>
      <inertia ixx="0.000221617" ixy="-1.44161e-06" ixz="1.46922e-05" iyy="0.000129193" iyz="4.22954e-06" izz="0.000175411"/>
    </inertial>
    <!-- Part part_8 -->
    <visual>
      <origin xyz="0 0 -0.006" rpy="0 -0 9.72346e-63"/>
      <geometry>
        <mesh filename="package://edulite_a3_description/meshes/part_8.stl"/>
      </geometry>
      <material name="part_8_material">
        <color rgba="0.980392 0.713725 0.00392157 1"/>
      </material>
    </visual>
    <collision>
      <origin xyz="0 0 -0.006" rpy="0 -0 9.72346e-63"/>
      <geometry>
        <mesh filename="package://edulite_a3_description/meshes/part_8.stl"/>
      </geometry>
    </collision>
    <!-- Part part_9 -->
    <visual>
      <origin xyz="0 0 -0.006" rpy="0 -0 9.72346e-63"/>
      <geometry>
        <mesh filename="package://edulite_a3_description/meshes/part_9.stl"/>
      </geometry>
      <material name="part_9_material">
        <color rgba="0.980392 0.713725 0.00392157 1"/>
      </material>
    </visual>
    <collision>
      <origin xyz="0 0 -0.006" rpy="0 -0 9.72346e-63"/>
      <geometry>
        <mesh filename="package://edulite_a3_description/meshes/part_9.stl"/>
      </geometry>
    </collision>
  </link>
  <!-- Link l2_l3_urdf_asm -->
  <link name="l2_l3_urdf_asm">
    <inertial>
      <origin xyz="0.0949994 -1.38262e-06 -0.00108795" rpy="0 0 0"/>
      <mass value="0.946534"/>
      <inertia ixx="0.000493341" ixy="6.92125e-07" ixz="-1.27006e-08" iyy="0.00767087" iyz="2.73309e-09" izz="0.0076934"/>
    </inertial>
    <!-- Part mainlink_back -->
    <visual>
      <origin xyz="0.01 -0.07 -0.0001" rpy="-1.5708 -6.13497e-17 -3.9443e-31"/>
      <geometry>
        <mesh filename="package://edulite_a3_description/meshes/mainlink_back.stl"/>
      </geometry>
      <material name="mainlink_back_material">
        <color rgba="0.647059 0.647059 0.647059 1"/>
      </material>
    </visual>
    <collision>
      <origin xyz="0.01 -0.07 -0.0001" rpy="-1.5708 -6.13497e-17 -3.9443e-31"/>
      <geometry>
        <mesh filename="package://edulite_a3_description/meshes/mainlink_back.stl"/>
      </geometry>
    </collision>
    <!-- Part 6705 -->
    <visual>
      <origin xyz="0.01 -0.07 -0.0001" rpy="-1.5708 -6.13497e-17 -3.9443e-31"/>
      <geometry>
        <mesh filename="package://edulite_a3_description/meshes/6705.stl"/>
      </geometry>
      <material name="6705_material">
        <color rgba="0.917647 0.917647 0.917647 1"/>
      </material>
    </visual>
    <collision>
      <origin xyz="0.01 -0.07 -0.0001" rpy="-1.5708 -6.13497e-17 -3.9443e-31"/>
      <geometry>
        <mesh filename="package://edulite_a3_description/meshes/6705.stl"/>
      </geometry>
    </collision>
    <!-- Part rs00_l2 -->
    <visual>
      <origin xyz="0.01 -0.07 -0.0006" rpy="-1.5708 -6.13497e-17 -3.9443e-31"/>
      <geometry>
        <mesh filename="package://edulite_a3_description/meshes/rs00_l2.stl"/>
      </geometry>
      <material name="rs00_l2_material">
        <color rgba="0.972549 0.529412 0.00392157 1"/>
      </material>
    </visual>
    <collision>
      <origin xyz="0.01 -0.07 -0.0006" rpy="-1.5708 -6.13497e-17 -3.9443e-31"/>
      <geometry>
        <mesh filename="package://edulite_a3_description/meshes/rs00_l2.stl"/>
      </geometry>
    </collision>
    <!-- Part mainlink_motor -->
    <visual>
      <origin xyz="0.01 -0.07 -0.0006" rpy="-1.5708 1.02326e-16 -2.77556e-17"/>
      <geometry>
        <mesh filename="package://edulite_a3_description/meshes/mainlink_motor.stl"/>
      </geometry>
      <material name="mainlink_motor_material">
        <color rgba="0.647059 0.647059 0.647059 1"/>
      </material>
    </visual>
    <collision>
      <origin xyz="0.01 -0.07 -0.0006" rpy="-1.5708 1.02326e-16 -2.77556e-17"/>
      <geometry>
        <mesh filename="package://edulite_a3_description/meshes/mainlink_motor.stl"/>
      </geometry>
    </collision>
    <!-- Part 6705_2 -->
    <visual>
      <origin xyz="0.01 -0.07 -0.0001" rpy="-1.5708 -6.13497e-17 -3.9443e-31"/>
      <geometry>
        <mesh filename="package://edulite_a3_description/meshes/6705__2.stl"/>
      </geometry>
      <material name="6705_2_material">
        <color rgba="0.231373 0.380392 0.705882 1"/>
      </material>
    </visual>
    <collision>
      <origin xyz="0.01 -0.07 -0.0001" rpy="-1.5708 -6.13497e-17 -3.9443e-31"/>
      <geometry>
        <mesh filename="package://edulite_a3_description/meshes/6705__2.stl"/>
      </geometry>
    </collision>
    <!-- Part rs00_l3 -->
    <visual>
      <origin xyz="0.01 -0.07 -0.0006" rpy="-1.5708 7.99958e-17 8.32667e-17"/>
      <geometry>
        <mesh filename="package://edulite_a3_description/meshes/rs00_l3.stl"/>
      </geometry>
      <material name="rs00_l3_material">
        <color rgba="0.972549 0.529412 0.00392157 1"/>
      </material>
    </visual>
    <collision>
      <origin xyz="0.01 -0.07 -0.0006" rpy="-1.5708 7.99958e-17 8.32667e-17"/>
      <geometry>
        <mesh filename="package://edulite_a3_description/meshes/rs00_l3.stl"/>
      </geometry>
    </collision>
  </link>
  <!-- Link l3_lnik_urdf_asm -->
  <link name="l3_lnik_urdf_asm">
    <inertial>
      <origin xyz="-0.0693243 0.0530595 -0.0510805" rpy="0 0 0"/>
      <mass value="0.406558"/>
      <inertia ixx="0.000554036" ixy="0.000274809" ixz="4.74842e-06" iyy="0.00189339" iyz="7.79959e-06" izz="0.00192037"/>
    </inertial>
    <!-- Part small_arm_right -->
    <visual>
      <origin xyz="-0.18 -0.07 -0.0518" rpy="-1.5708 2.12834e-33 5.29631e-33"/>
      <geometry>
        <mesh filename="package://edulite_a3_description/meshes/small_arm_right.stl"/>
      </geometry>
      <material name="small_arm_right_material">
        <color rgba="0.972549 0.529412 0.00392157 1"/>
      </material>
    </visual>
    <collision>
      <origin xyz="-0.18 -0.07 -0.0518" rpy="-1.5708 2.12834e-33 5.29631e-33"/>
      <geometry>
        <mesh filename="package://edulite_a3_description/meshes/small_arm_right.stl"/>
      </geometry>
    </collision>
    <!-- Part small_arm_left -->
    <visual>
      <origin xyz="-0.18 -0.07 -0.0518" rpy="-1.5708 2.12834e-33 5.29631e-33"/>
      <geometry>
        <mesh filename="package://edulite_a3_description/meshes/small_arm_left.stl"/>
      </geometry>
      <material name="small_arm_left_material">
        <color rgba="0.972549 0.529412 0.00392157 1"/>
      </material>
    </visual>
    <collision>
      <origin xyz="-0.18 -0.07 -0.0518" rpy="-1.5708 2.12834e-33 5.29631e-33"/>
      <geometry>
        <mesh filename="package://edulite_a3_description/meshes/small_arm_left.stl"/>
      </geometry>
    </collision>
  </link>
  <!-- Link l4_l5_urdf_asm -->
  <link name="l4_l5_urdf_asm">
    <inertial>
      <origin xyz="-0.0241077 0.0297756 -0.000254349" rpy="0 0 0"/>
      <mass value="0.44692"/>
      <inertia ixx="0.000543249" ixy="0.000320527" ixz="2.88671e-06" iyy="0.00040341" iyz="-3.57587e-06" izz="0.000797799"/>
    </inertial>
    <!-- Part rs05_l5 -->
    <visual>
      <origin xyz="0.005 -0.134 2.4503e-16" rpy="-1.5708 -1.95896e-16 -5.55112e-17"/>
      <geometry>
        <mesh filename="package://edulite_a3_description/meshes/rs05_l5.stl"/>
      </geometry>
      <material name="rs05_l5_material">
        <color rgba="1 1 1 1"/>
      </material>
    </visual>
    <collision>
      <origin xyz="0.005 -0.134 2.4503e-16" rpy="-1.5708 -1.95896e-16 -5.55112e-17"/>
      <geometry>
        <mesh filename="package://edulite_a3_description/meshes/rs05_l5.stl"/>
      </geometry>
    </collision>
    <!-- Part l5_shake -->
    <visual>
      <origin xyz="0.005 -0.134 3.00541e-16" rpy="-1.5708 -1.95896e-16 -5.55112e-17"/>
      <geometry>
        <mesh filename="package://edulite_a3_description/meshes/l5_shake.stl"/>
      </geometry>
      <material name="l5_shake_material">
        <color rgba="0.768627 0.886275 0.952941 1"/>
      </material>
    </visual>
    <collision>
      <origin xyz="0.005 -0.134 3.00541e-16" rpy="-1.5708 -1.95896e-16 -5.55112e-17"/>
      <geometry>
        <mesh filename="package://edulite_a3_description/meshes/l5_shake.stl"/>
      </geometry>
    </collision>
    <!-- Part l4_l5_link_back -->
    <visual>
      <origin xyz="0.005 -0.134 4.42788e-16" rpy="-1.5708 7.76068e-15 -1.64799e-16"/>
      <geometry>
        <mesh filename="package://edulite_a3_description/meshes/l4_l5_link_back.stl"/>
      </geometry>
      <material name="l4_l5_link_back_material">
        <color rgba="0.972549 0.529412 0.00392157 1"/>
      </material>
    </visual>
    <collision>
      <origin xyz="0.005 -0.134 4.42788e-16" rpy="-1.5708 7.76068e-15 -1.64799e-16"/>
      <geometry>
        <mesh filename="package://edulite_a3_description/meshes/l4_l5_link_back.stl"/>
      </geometry>
    </collision>
    <!-- Part rs05_l4 -->
    <visual>
      <origin xyz="0.005 -0.134 2.86663e-16" rpy="-1.5708 2.11734e-33 0"/>
      <geometry>
        <mesh filename="package://edulite_a3_description/meshes/rs05_l4.stl"/>
      </geometry>
      <material name="rs05_l4_material">
        <color rgba="1 1 1 1"/>
      </material>
    </visual>
    <collision>
      <origin xyz="0.005 -0.134 2.86663e-16" rpy="-1.5708 2.11734e-33 0"/>
      <geometry>
        <mesh filename="package://edulite_a3_description/meshes/rs05_l4.stl"/>
      </geometry>
    </collision>
    <!-- Part l4_l5_link_back_2 -->
    <visual>
      <origin xyz="0.005 -0.134 4.42788e-16" rpy="-1.5708 7.76068e-15 -1.64799e-16"/>
      <geometry>
        <mesh filename="package://edulite_a3_description/meshes/l4_l5_link_back__2.stl"/>
      </geometry>
      <material name="l4_l5_link_back_2_material">
        <color rgba="0.972549 0.529412 0.00392157 1"/>
      </material>
    </visual>
    <collision>
      <origin xyz="0.005 -0.134 4.42788e-16" rpy="-1.5708 7.76068e-15 -1.64799e-16"/>
      <geometry>
        <mesh filename="package://edulite_a3_description/meshes/l4_l5_link_back__2.stl"/>
      </geometry>
    </collision>
  </link>
  <!-- Link part_9 -->
  <link name="part_9">
    <inertial>
      <origin xyz="0.00409255 -1.048e-08 0.0175119" rpy="0 0 0"/>
      <mass value="0.0179457"/>
      <inertia ixx="5.21252e-06" ixy="8.94026e-13" ixz="-1.22446e-06" iyy="5.09672e-06" iyz="2.59479e-13" izz="2.51083e-06"/>
    </inertial>
    <!-- Part part_9_2 -->
    <visual>
      <origin xyz="0.0542 -2.50776e-16 0.172" rpy="3.14159 1.54074e-33 -4.6512e-33"/>
      <geometry>
        <mesh filename="package://edulite_a3_description/meshes/part_9__2.stl"/>
      </geometry>
      <material name="part_9_2_material">
        <color rgba="0.972549 0.529412 0.00392157 1"/>
      </material>
    </visual>
    <collision>
      <origin xyz="0.0542 -2.50776e-16 0.172" rpy="3.14159 1.54074e-33 -4.6512e-33"/>
      <geometry>
        <mesh filename="package://edulite_a3_description/meshes/part_9__2.stl"/>
      </geometry>
    </collision>
  </link>
  <!-- Link l5_l6_urdf_asm -->
  <link name="l5_l6_urdf_asm">
    <inertial>
      <origin xyz="-1.16996e-05 0.000627615 -0.0701883" rpy="0 0 0"/>
      <mass value="0.5317"/>
      <inertia ixx="0.00100405" ixy="-4.97095e-06" ixz="1.06714e-07" iyy="0.00139953" iyz="1.65952e-05" izz="0.00054217"/>
    </inertial>
    <!-- Part part_4 -->
    <visual>
      <origin xyz="-1.77809e-16 1.94289e-16 -0.062" rpy="3.14159 -1.5708 0"/>
      <geometry>
        <mesh filename="package://edulite_a3_description/meshes/part_4.stl"/>
      </geometry>
      <material name="part_4_material">
        <color rgba="0.647059 0.647059 0.647059 1"/>
      </material>
    </visual>
    <collision>
      <origin xyz="-1.77809e-16 1.94289e-16 -0.062" rpy="3.14159 -1.5708 0"/>
      <geometry>
        <mesh filename="package://edulite_a3_description/meshes/part_4.stl"/>
      </geometry>
    </collision>
    <!-- Part hand_r -->
    <visual>
      <origin xyz="7.53017e-05 2.02616e-15 -0.0755" rpy="3.14159 -3.4053e-16 -3.54751e-16"/>
      <geometry>
        <mesh filename="package://edulite_a3_description/meshes/hand_r.stl"/>
      </geometry>
      <material name="hand_r_material">
        <color rgba="0.231373 0.380392 0.705882 1"/>
      </material>
    </visual>
    <collision>
      <origin xyz="7.53017e-05 2.02616e-15 -0.0755" rpy="3.14159 -3.4053e-16 -3.54751e-16"/>
      <geometry>
        <mesh filename="package://edulite_a3_description/meshes/hand_r.stl"/>
      </geometry>
    </collision>
    <!-- Part rs05 -->
    <visual>
      <origin xyz="-1.09157e-15 2.30371e-15 -0.0755" rpy="-3.14159 -5.37371e-16 -5.2367e-16"/>
      <geometry>
        <mesh filename="package://edulite_a3_description/meshes/rs05.stl"/>
      </geometry>
      <material name="rs05_material">
        <color rgba="1 1 1 1"/>
      </material>
    </visual>
    <collision>
      <origin xyz="-1.09157e-15 2.30371e-15 -0.0755" rpy="-3.14159 -5.37371e-16 -5.2367e-16"/>
      <geometry>
        <mesh filename="package://edulite_a3_description/meshes/rs05.stl"/>
      </geometry>
    </collision>
    <!-- Part rack__30_teeth -->
    <visual>
      <origin xyz="7.53017e-05 1.91513e-15 -0.0755" rpy="-3.14159 -6.1311e-17 -2.48499e-16"/>
      <geometry>
        <mesh filename="package://edulite_a3_description/meshes/rack__30_teeth.stl"/>
      </geometry>
      <material name="rack__30_teeth_material">
        <color rgba="0.917647 0.917647 0.917647 1"/>
      </material>
    </visual>
    <collision>
      <origin xyz="7.53017e-05 1.91513e-15 -0.0755" rpy="-3.14159 -6.1311e-17 -2.48499e-16"/>
      <geometry>
        <mesh filename="package://edulite_a3_description/meshes/rack__30_teeth.stl"/>
      </geometry>
    </collision>
    <!-- Part manifold_solid_brep_39_1 -->
    <visual>
      <origin xyz="0.003 1.9984e-15 -0.0755" rpy="-3.14159 -1.72679e-16 -2.70183e-16"/>
      <geometry>
        <mesh filename="package://edulite_a3_description/meshes/manifold_solid_brep_39_1.stl"/>
      </geometry>
      <material name="manifold_solid_brep_39_1_material">
        <color rgba="0.980392 0.713725 0.00392157 1"/>
      </material>
    </visual>
    <collision>
      <origin xyz="0.003 1.9984e-15 -0.0755" rpy="-3.14159 -1.72679e-16 -2.70183e-16"/>
      <geometry>
        <mesh filename="package://edulite_a3_description/meshes/manifold_solid_brep_39_1.stl"/>
      </geometry>
    </collision>
    <!-- Part rack__30_teeth_2 -->
    <visual>
      <origin xyz="-7.53017e-05 2.33147e-15 -0.0755" rpy="-3.14159 -3.81435e-16 -3.05962e-16"/>
      <geometry>
        <mesh filename="package://edulite_a3_description/meshes/rack__30_teeth__2.stl"/>
      </geometry>
      <material name="rack__30_teeth_2_material">
        <color rgba="0.917647 0.917647 0.917647 1"/>
      </material>
    </visual>
    <collision>
      <origin xyz="-7.53017e-05 2.33147e-15 -0.0755" rpy="-3.14159 -3.81435e-16 -3.05962e-16"/>
      <geometry>
        <mesh filename="package://edulite_a3_description/meshes/rack__30_teeth__2.stl"/>
      </geometry>
    </collision>
    <!-- Part manifold_solid_brep_39_1_2 -->
    <visual>
      <origin xyz="-0.003 1.94289e-15 -0.0755" rpy="-3.14159 -1.72679e-16 -2.70183e-16"/>
      <geometry>
        <mesh filename="package://edulite_a3_description/meshes/manifold_solid_brep_39_1__2.stl"/>
      </geometry>
      <material name="manifold_solid_brep_39_1_2_material">
        <color rgba="0.980392 0.713725 0.00392157 1"/>
      </material>
    </visual>
    <collision>
      <origin xyz="-0.003 1.94289e-15 -0.0755" rpy="-3.14159 -1.72679e-16 -2.70183e-16"/>
      <geometry>
        <mesh filename="package://edulite_a3_description/meshes/manifold_solid_brep_39_1__2.stl"/>
      </geometry>
    </collision>
    <!-- Part rack_base -->
    <visual>
      <origin xyz="-1.11933e-15 2.33147e-15 -0.0755" rpy="-3.14159 -4.38532e-16 -4.11563e-16"/>
      <geometry>
        <mesh filename="package://edulite_a3_description/meshes/rack_base.stl"/>
      </geometry>
      <material name="rack_base_material">
        <color rgba="0.768627 0.886275 0.952941 1"/>
      </material>
    </visual>
    <collision>
      <origin xyz="-1.11933e-15 2.33147e-15 -0.0755" rpy="-3.14159 -4.38532e-16 -4.11563e-16"/>
      <geometry>
        <mesh filename="package://edulite_a3_description/meshes/rack_base.stl"/>
      </geometry>
    </collision>
    <!-- Part rack_str -->
    <visual>
      <origin xyz="-1.11933e-15 2.33147e-15 -0.0755" rpy="-3.14159 -4.38532e-16 -4.11563e-16"/>
      <geometry>
        <mesh filename="package://edulite_a3_description/meshes/rack_str.stl"/>
      </geometry>
      <material name="rack_str_material">
        <color rgba="0.768627 0.886275 0.952941 1"/>
      </material>
    </visual>
    <collision>
      <origin xyz="-1.11933e-15 2.33147e-15 -0.0755" rpy="-3.14159 -4.38532e-16 -4.11563e-16"/>
      <geometry>
        <mesh filename="package://edulite_a3_description/meshes/rack_str.stl"/>
      </geometry>
    </collision>
    <!-- Part part_3 -->
    <visual>
      <origin xyz="-1.29063e-15 2.19269e-15 -0.062" rpy="3.14159 -1.5708 0"/>
      <geometry>
        <mesh filename="package://edulite_a3_description/meshes/part_3.stl"/>
      </geometry>
      <material name="part_3_material">
        <color rgba="0.615686 0.811765 0.929412 1"/>
      </material>
    </visual>
    <collision>
      <origin xyz="-1.29063e-15 2.19269e-15 -0.062" rpy="3.14159 -1.5708 0"/>
      <geometry>
        <mesh filename="package://edulite_a3_description/meshes/part_3.stl"/>
      </geometry>
    </collision>
    <!-- Part rs05_2 -->
    <visual>
      <origin xyz="2.64545e-17 1.38778e-16 -0.0305" rpy="2.53064e-15 -6.05486e-16 -4.37367e-16"/>
      <geometry>
        <mesh filename="package://edulite_a3_description/meshes/rs05.stl"/>
      </geometry>
      <material name="rs05_2_material">
        <color rgba="1 1 1 1"/>
      </material>
    </visual>
    <collision>
      <origin xyz="2.64545e-17 1.38778e-16 -0.0305" rpy="2.53064e-15 -6.05486e-16 -4.37367e-16"/>
      <geometry>
        <mesh filename="package://edulite_a3_description/meshes/rs05.stl"/>
      </geometry>
    </collision>
    <!-- Part spur_gear__14_teeth -->
    <visual>
      <origin xyz="-1.95421e-14 -6.41154e-15 -0.0755" rpy="-3.14159 -4.38532e-16 -4.11563e-16"/>
      <geometry>
        <mesh filename="package://edulite_a3_description/meshes/spur_gear__14_teeth.stl"/>
      </geometry>
      <material name="spur_gear__14_teeth_material">
        <color rgba="0.917647 0.917647 0.917647 1"/>
      </material>
    </visual>
    <collision>
      <origin xyz="-1.95421e-14 -6.41154e-15 -0.0755" rpy="-3.14159 -4.38532e-16 -4.11563e-16"/>
      <geometry>
        <mesh filename="package://edulite_a3_description/meshes/spur_gear__14_teeth.stl"/>
      </geometry>
    </collision>
    <!-- Part part_15 -->
    <visual>
      <origin xyz="-7.53017e-05 2.02616e-15 -0.0755" rpy="-3.14159 -5.62273e-16 -3.31332e-16"/>
      <geometry>
        <mesh filename="package://edulite_a3_description/meshes/part_15.stl"/>
      </geometry>
      <material name="part_15_material">
        <color rgba="0.231373 0.380392 0.705882 1"/>
      </material>
    </visual>
    <collision>
      <origin xyz="-7.53017e-05 2.02616e-15 -0.0755" rpy="-3.14159 -5.62273e-16 -3.31332e-16"/>
      <geometry>
        <mesh filename="package://edulite_a3_description/meshes/part_15.stl"/>
      </geometry>
    </collision>
    <!-- Part manifold_solid_brep_40_1 -->
    <visual>
      <origin xyz="-1.11933e-15 2.30371e-15 -0.0755" rpy="-3.14159 -1.72679e-16 -2.70183e-16"/>
      <geometry>
        <mesh filename="package://edulite_a3_description/meshes/manifold_solid_brep_40_1.stl"/>
      </geometry>
      <material name="manifold_solid_brep_40_1_material">
        <color rgba="0.498039 0.498039 0.498039 1"/>
      </material>
    </visual>
    <collision>
      <origin xyz="-1.11933e-15 2.30371e-15 -0.0755" rpy="-3.14159 -1.72679e-16 -2.70183e-16"/>
      <geometry>
        <mesh filename="package://edulite_a3_description/meshes/manifold_solid_brep_40_1.stl"/>
      </geometry>
    </collision>
  </link>
  <!-- Joint from part_9 to l5_l6_urdf_asm -->
  <joint name="L6_joint" type="revolute">
    <origin xyz="0.00805 -2.47957e-16 0.038" rpy="-1.5708 -5.60446e-32 -1.5708"/>
    <parent link="part_9"/>
    <child link="l5_l6_urdf_asm"/>
    <axis xyz="0 0 1"/>
    <limit effort="10" velocity="10" lower="-1.5708" upper="1.5708"/>
  </joint>
  <!-- Joint from l4_l5_urdf_asm to part_9 -->
  <joint name="L5_joint" type="revolute">
    <origin xyz="-0.0492 0.038 5.24537e-16" rpy="1.5708 -1.89036e-16 1.56125e-17"/>
    <parent link="l4_l5_urdf_asm"/>
    <child link="part_9"/>
    <axis xyz="0 0 1"/>
    <limit effort="10" velocity="10" lower="-1.5708" upper="1.5708"/>
  </joint>
  <!-- Joint from l3_lnik_urdf_asm to l4_l5_urdf_asm -->
  <joint name="L4_joint" type="revolute">
    <origin xyz="-0.185 0.064 -0.0518" rpy="2.5974e-22 2.98284e-23 -4.33681e-19"/>
    <parent link="l3_lnik_urdf_asm"/>
    <child link="l4_l5_urdf_asm"/>
    <axis xyz="0 0 1"/>
    <limit effort="10" velocity="10" lower="-1.5708" upper="1.5708"/>
  </joint>
  <!-- Joint from l2_l3_urdf_asm to l3_lnik_urdf_asm -->
  <joint name="L3_joint" type="revolute">
    <origin xyz="0.19 1.249e-16 0.0518" rpy="2.54281e-17 7.99959e-17 8.37004e-17"/>
    <parent link="l2_l3_urdf_asm"/>
    <child link="l3_lnik_urdf_asm"/>
    <axis xyz="0 0 1"/>
    <limit effort="10" velocity="10" lower="-4.01426" upper="0"/>
  </joint>
  <!-- Joint from l1_link_urdf_asm to l2_l3_urdf_asm -->
  <joint name="L2_joint" type="revolute">
    <origin xyz="-0.01 -0.0006 0.064" rpy="1.5708 -0 9.72346e-63"/>
    <parent link="l1_link_urdf_asm"/>
    <child link="l2_l3_urdf_asm"/>
    <axis xyz="0 0 1"/>
    <limit effort="10" velocity="10" lower="-0" upper="3.66519"/>
  </joint>
  <!-- Joint from l1_urdf_urdf_asm to l1_link_urdf_asm -->
  <joint name="L1_joint" type="revolute">
    <origin xyz="0 0 0.006" rpy="0 -0 0"/>
    <parent link="l1_urdf_urdf_asm"/>
    <child link="l1_link_urdf_asm"/>
    <axis xyz="0 0 1"/>
    <limit effort="10" velocity="10" lower="-2.79253" upper="2.79253"/>
  </joint>
</robot>
