<?xml version="1.0" ?>
<!-- EL-A3 6-DOF Robot Arm URDF with ros2_control support -->
<!-- Updated from EDULITE-A3 model -->
<robot name="EL-A3" xmlns:xacro="http://www.ros.org/wiki/xacro">

  <!-- Arguments -->
  <xacro:arg name="use_mock_hardware" default="false"/>
  <xacro:arg name="can_interface" default="can0"/>
  <xacro:arg name="host_can_id" default="253"/>
  
  <!-- Include ros2_control -->
  <xacro:include filename="$(find el_a3_description)/urdf/el_a3_ros2_control.xacro"/>

  <!-- Materials -->
  <material name="orange">
    <color rgba="0.972549 0.529412 0.00392157 1"/>
  </material>
  <material name="gray">
    <color rgba="0.647059 0.647059 0.647059 1"/>
  </material>
  <material name="light_blue">
    <color rgba="0.768627 0.886275 0.952941 1"/>
  </material>
  <material name="white">
    <color rgba="0.917647 0.917647 0.917647 1"/>
  </material>
  <material name="dark_gray">
    <color rgba="0.301961 0.301961 0.301961 1"/>
  </material>
  <material name="blue">
    <color rgba="0.231373 0.380392 0.705882 1"/>
  </material>
  <material name="yellow">
    <color rgba="0.980392 0.713725 0.00392157 1"/>
  </material>
  <material name="green">
    <color rgba="0.372549 0.654902 0.239216 1"/>
  </material>

  <!-- Base link (world) -->
  <link name="base_link"/>
  
  <joint name="base_to_l1" type="fixed">
    <parent link="base_link"/>
    <child link="l1_urdf_urdf_asm"/>
    <origin xyz="0 0 0" rpy="0 0 0"/>
  </joint>

  <!-- Link l1_urdf_urdf_asm (Base) -->
  <link name="l1_urdf_urdf_asm">
    <inertial>
      <origin xyz="-2.68984e-10 1.48294e-05 -0.0220571" rpy="0 0 0"/>
      <mass value="0.465144"/>
      <inertia ixx="0.00032748" ixy="-1.33894e-08" ixz="-1.85358e-12" 
               iyy="0.000321793" iyz="-2.46949e-07" izz="0.000362426"/>
    </inertial>
    <!-- Part part_10 -->
    <visual>
      <origin xyz="0 0 0" rpy="0 0 0"/>
      <geometry>
        <mesh filename="package://el_a3_description/meshes/part_10.stl"/>
      </geometry>
      <material name="green"/>
    </visual>
    <collision>
      <origin xyz="0 0 0" rpy="0 0 0"/>
      <geometry>
        <mesh filename="package://el_a3_description/meshes/part_10.stl"/>
      </geometry>
    </collision>
    <!-- Part rs00_l1 -->
    <visual>
      <origin xyz="0 0 0" rpy="0 0 0"/>
      <geometry>
        <mesh filename="package://el_a3_description/meshes/rs00_l1.stl"/>
      </geometry>
      <material name="orange"/>
    </visual>
    <collision>
      <origin xyz="0 0 0" rpy="0 0 0"/>
      <geometry>
        <mesh filename="package://el_a3_description/meshes/rs00_l1.stl"/>
      </geometry>
    </collision>
  </link>

  <!-- Link l1_link_urdf_asm -->
  <link name="l1_link_urdf_asm">
    <inertial>
      <origin xyz="-0.00202103 -0.00162495 0.0394318" rpy="0 0 0"/>
      <mass value="0.146738"/>
      <inertia ixx="0.000221617" ixy="-1.44161e-06" ixz="1.46922e-05" 
               iyy="0.000129193" iyz="4.22954e-06" izz="0.000175411"/>
    </inertial>
    <!-- Part part_8 -->
    <visual>
      <origin xyz="0 0 -0.006" rpy="0 0 0"/>
      <geometry>
        <mesh filename="package://el_a3_description/meshes/part_8.stl"/>
      </geometry>
      <material name="yellow"/>
    </visual>
    <collision>
      <origin xyz="0 0 -0.006" rpy="0 0 0"/>
      <geometry>
        <mesh filename="package://el_a3_description/meshes/part_8.stl"/>
      </geometry>
    </collision>
    <!-- Part part_9 -->
    <visual>
      <origin xyz="0 0 -0.006" rpy="0 0 0"/>
      <geometry>
        <mesh filename="package://el_a3_description/meshes/part_9.stl"/>
      </geometry>
      <material name="yellow"/>
    </visual>
    <collision>
      <origin xyz="0 0 -0.006" rpy="0 0 0"/>
      <geometry>
        <mesh filename="package://el_a3_description/meshes/part_9.stl"/>
      </geometry>
    </collision>
  </link>

  <!-- Link l2_l3_urdf_asm -->
  <link name="l2_l3_urdf_asm">
    <inertial>
      <origin xyz="0.0949994 -1.38262e-06 -0.00108795" rpy="0 0 0"/>
      <mass value="0.946534"/>
      <inertia ixx="0.000493341" ixy="6.92125e-07" ixz="-1.27006e-08" 
               iyy="0.00767087" iyz="2.73309e-09" izz="0.0076934"/>
    </inertial>
    <!-- Part mainlink_back -->
    <visual>
      <origin xyz="0.01 -0.07 -0.0001" rpy="-1.5708 0 0"/>
      <geometry>
        <mesh filename="package://el_a3_description/meshes/mainlink_back.stl"/>
      </geometry>
      <material name="gray"/>
    </visual>
    <collision>
      <origin xyz="0.01 -0.07 -0.0001" rpy="-1.5708 0 0"/>
      <geometry>
        <mesh filename="package://el_a3_description/meshes/mainlink_back.stl"/>
      </geometry>
    </collision>
    <!-- Part 6705 -->
    <visual>
      <origin xyz="0.01 -0.07 -0.0001" rpy="-1.5708 0 0"/>
      <geometry>
        <mesh filename="package://el_a3_description/meshes/6705.stl"/>
      </geometry>
      <material name="white"/>
    </visual>
    <collision>
      <origin xyz="0.01 -0.07 -0.0001" rpy="-1.5708 0 0"/>
      <geometry>
        <mesh filename="package://el_a3_description/meshes/6705.stl"/>
      </geometry>
    </collision>
    <!-- Part rs00_l2 -->
    <visual>
      <origin xyz="0.01 -0.07 -0.0006" rpy="-1.5708 0 0"/>
      <geometry>
        <mesh filename="package://el_a3_description/meshes/rs00_l2.stl"/>
      </geometry>
      <material name="orange"/>
    </visual>
    <collision>
      <origin xyz="0.01 -0.07 -0.0006" rpy="-1.5708 0 0"/>
      <geometry>
        <mesh filename="package://el_a3_description/meshes/rs00_l2.stl"/>
      </geometry>
    </collision>
    <!-- Part mainlink_motor -->
    <visual>
      <origin xyz="0.01 -0.07 -0.0006" rpy="-1.5708 0 0"/>
      <geometry>
        <mesh filename="package://el_a3_description/meshes/mainlink_motor.stl"/>
      </geometry>
      <material name="gray"/>
    </visual>
    <collision>
      <origin xyz="0.01 -0.07 -0.0006" rpy="-1.5708 0 0"/>
      <geometry>
        <mesh filename="package://el_a3_description/meshes/mainlink_motor.stl"/>
      </geometry>
    </collision>
    <!-- Part 6705_2 -->
    <visual>
      <origin xyz="0.01 -0.07 -0.0001" rpy="-1.5708 0 0"/>
      <geometry>
        <mesh filename="package://el_a3_description/meshes/6705__2.stl"/>
      </geometry>
      <material name="blue"/>
    </visual>
    <collision>
      <origin xyz="0.01 -0.07 -0.0001" rpy="-1.5708 0 0"/>
      <geometry>
        <mesh filename="package://el_a3_description/meshes/6705__2.stl"/>
      </geometry>
    </collision>
    <!-- Part rs00_l3 -->
    <visual>
      <origin xyz="0.01 -0.07 -0.0006" rpy="-1.5708 0 0"/>
      <geometry>
        <mesh filename="package://el_a3_description/meshes/rs00_l3.stl"/>
      </geometry>
      <material name="orange"/>
    </visual>
    <collision>
      <origin xyz="0.01 -0.07 -0.0006" rpy="-1.5708 0 0"/>
      <geometry>
        <mesh filename="package://el_a3_description/meshes/rs00_l3.stl"/>
      </geometry>
    </collision>
  </link>

  <!-- Link l3_lnik_urdf_asm -->
  <link name="l3_lnik_urdf_asm">
    <inertial>
      <origin xyz="-0.0693243 0.0530595 -0.0510805" rpy="0 0 0"/>
      <mass value="0.406558"/>
      <inertia ixx="0.000554036" ixy="0.000274809" ixz="4.74842e-06" 
               iyy="0.00189339" iyz="7.79959e-06" izz="0.00192037"/>
    </inertial>
    <!-- Part small_arm_right -->
    <visual>
      <origin xyz="-0.18 -0.07 -0.0518" rpy="-1.5708 0 0"/>
      <geometry>
        <mesh filename="package://el_a3_description/meshes/small_arm_right.stl"/>
      </geometry>
      <material name="orange"/>
    </visual>
    <collision>
      <origin xyz="-0.18 -0.07 -0.0518" rpy="-1.5708 0 0"/>
      <geometry>
        <mesh filename="package://el_a3_description/meshes/small_arm_right.stl"/>
      </geometry>
    </collision>
    <!-- Part small_arm_left -->
    <visual>
      <origin xyz="-0.18 -0.07 -0.0518" rpy="-1.5708 0 0"/>
      <geometry>
        <mesh filename="package://el_a3_description/meshes/small_arm_left.stl"/>
      </geometry>
      <material name="orange"/>
    </visual>
    <collision>
      <origin xyz="-0.18 -0.07 -0.0518" rpy="-1.5708 0 0"/>
      <geometry>
        <mesh filename="package://el_a3_description/meshes/small_arm_left.stl"/>
      </geometry>
    </collision>
  </link>

  <!-- Link l4_l5_urdf_asm -->
  <link name="l4_l5_urdf_asm">
    <inertial>
      <origin xyz="-0.0241077 0.0297756 -0.000254349" rpy="0 0 0"/>
      <mass value="0.44692"/>
      <inertia ixx="0.000543249" ixy="0.000320527" ixz="2.88671e-06" 
               iyy="0.00040341" iyz="-3.57587e-06" izz="0.000797799"/>
    </inertial>
    <!-- Part el05_l5 -->
    <visual>
      <origin xyz="0.005 -0.134 0" rpy="-1.5708 0 0"/>
      <geometry>
        <mesh filename="package://el_a3_description/meshes/el05_l5.stl"/>
      </geometry>
      <material name="white"/>
    </visual>
    <collision>
      <origin xyz="0.005 -0.134 0" rpy="-1.5708 0 0"/>
      <geometry>
        <mesh filename="package://el_a3_description/meshes/el05_l5.stl"/>
      </geometry>
    </collision>
    <!-- Part l5_shake -->
    <visual>
      <origin xyz="0.005 -0.134 0" rpy="-1.5708 0 0"/>
      <geometry>
        <mesh filename="package://el_a3_description/meshes/l5_shake.stl"/>
      </geometry>
      <material name="light_blue"/>
    </visual>
    <collision>
      <origin xyz="0.005 -0.134 0" rpy="-1.5708 0 0"/>
      <geometry>
        <mesh filename="package://el_a3_description/meshes/l5_shake.stl"/>
      </geometry>
    </collision>
    <!-- Part l4_l5_link_back -->
    <visual>
      <origin xyz="0.005 -0.134 0" rpy="-1.5708 0 0"/>
      <geometry>
        <mesh filename="package://el_a3_description/meshes/l4_l5_link_back.stl"/>
      </geometry>
      <material name="orange"/>
    </visual>
    <collision>
      <origin xyz="0.005 -0.134 0" rpy="-1.5708 0 0"/>
      <geometry>
        <mesh filename="package://el_a3_description/meshes/l4_l5_link_back.stl"/>
      </geometry>
    </collision>
    <!-- Part el05_l4 -->
    <visual>
      <origin xyz="0.005 -0.134 0" rpy="-1.5708 0 0"/>
      <geometry>
        <mesh filename="package://el_a3_description/meshes/el05_l4.stl"/>
      </geometry>
      <material name="white"/>
    </visual>
    <collision>
      <origin xyz="0.005 -0.134 0" rpy="-1.5708 0 0"/>
      <geometry>
        <mesh filename="package://el_a3_description/meshes/el05_l4.stl"/>
      </geometry>
    </collision>
    <!-- Part l4_l5_link_back_2 -->
    <visual>
      <origin xyz="0.005 -0.134 0" rpy="-1.5708 0 0"/>
      <geometry>
        <mesh filename="package://el_a3_description/meshes/l4_l5_link_back__2.stl"/>
      </geometry>
      <material name="orange"/>
    </visual>
    <collision>
      <origin xyz="0.005 -0.134 0" rpy="-1.5708 0 0"/>
      <geometry>
        <mesh filename="package://el_a3_description/meshes/l4_l5_link_back__2.stl"/>
      </geometry>
    </collision>
  </link>

  <!-- Link part_9 -->
  <link name="part_9">
    <inertial>
      <origin xyz="0.00409255 0 0.0175119" rpy="0 0 0"/>
      <mass value="0.0179457"/>
      <inertia ixx="5.21252e-06" ixy="0" ixz="-1.22446e-06" 
               iyy="5.09672e-06" iyz="0" izz="2.51083e-06"/>
    </inertial>
    <!-- Part part_9_2 -->
    <visual>
      <origin xyz="0.0542 0 0.172" rpy="3.14159 0 0"/>
      <geometry>
        <mesh filename="package://el_a3_description/meshes/part_9__2.stl"/>
      </geometry>
      <material name="orange"/>
    </visual>
    <collision>
      <origin xyz="0.0542 0 0.172" rpy="3.14159 0 0"/>
      <geometry>
        <mesh filename="package://el_a3_description/meshes/part_9__2.stl"/>
      </geometry>
    </collision>
  </link>

  <!-- Link l5_l6_urdf_asm (End Effector) -->
  <link name="l5_l6_urdf_asm">
    <inertial>
      <origin xyz="-1.16996e-05 0.000627615 -0.0701883" rpy="0 0 0"/>
      <mass value="0.5317"/>
      <inertia ixx="0.00100405" ixy="-4.97095e-06" ixz="1.06714e-07" 
               iyy="0.00139953" iyz="1.65952e-05" izz="0.00054217"/>
    </inertial>
    <!-- Part part_4 -->
    <visual>
      <origin xyz="0 0 -0.062" rpy="3.14159 -1.5708 0"/>
      <geometry>
        <mesh filename="package://el_a3_description/meshes/part_4.stl"/>
      </geometry>
      <material name="gray"/>
    </visual>
    <collision>
      <origin xyz="0 0 -0.062" rpy="3.14159 -1.5708 0"/>
      <geometry>
        <mesh filename="package://el_a3_description/meshes/part_4.stl"/>
      </geometry>
    </collision>
    <!-- Part hand_r -->
    <visual>
      <origin xyz="0 0 -0.0755" rpy="3.14159 0 0"/>
      <geometry>
        <mesh filename="package://el_a3_description/meshes/hand_r.stl"/>
      </geometry>
      <material name="blue"/>
    </visual>
    <collision>
      <origin xyz="0 0 -0.0755" rpy="3.14159 0 0"/>
      <geometry>
        <mesh filename="package://el_a3_description/meshes/hand_r.stl"/>
      </geometry>
    </collision>
    <!-- Part el05 -->
    <visual>
      <origin xyz="0 0 -0.0755" rpy="-3.14159 0 0"/>
      <geometry>
        <mesh filename="package://el_a3_description/meshes/el05.stl"/>
      </geometry>
      <material name="white"/>
    </visual>
    <collision>
      <origin xyz="0 0 -0.0755" rpy="-3.14159 0 0"/>
      <geometry>
        <mesh filename="package://el_a3_description/meshes/el05.stl"/>
      </geometry>
    </collision>
    <!-- Part rack__30_teeth -->
    <visual>
      <origin xyz="0 0 -0.0755" rpy="-3.14159 0 0"/>
      <geometry>
        <mesh filename="package://el_a3_description/meshes/rack__30_teeth.stl"/>
      </geometry>
      <material name="white"/>
    </visual>
    <collision>
      <origin xyz="0 0 -0.0755" rpy="-3.14159 0 0"/>
      <geometry>
        <mesh filename="package://el_a3_description/meshes/rack__30_teeth.stl"/>
      </geometry>
    </collision>
    <!-- Part manifold_solid_brep_39_1 -->
    <visual>
      <origin xyz="0.003 0 -0.0755" rpy="-3.14159 0 0"/>
      <geometry>
        <mesh filename="package://el_a3_description/meshes/manifold_solid_brep_39_1.stl"/>
      </geometry>
      <material name="yellow"/>
    </visual>
    <collision>
      <origin xyz="0.003 0 -0.0755" rpy="-3.14159 0 0"/>
      <geometry>
        <mesh filename="package://el_a3_description/meshes/manifold_solid_brep_39_1.stl"/>
      </geometry>
    </collision>
    <!-- Part rack__30_teeth_2 -->
    <visual>
      <origin xyz="0 0 -0.0755" rpy="-3.14159 0 0"/>
      <geometry>
        <mesh filename="package://el_a3_description/meshes/rack__30_teeth__2.stl"/>
      </geometry>
      <material name="white"/>
    </visual>
    <collision>
      <origin xyz="0 0 -0.0755" rpy="-3.14159 0 0"/>
      <geometry>
        <mesh filename="package://el_a3_description/meshes/rack__30_teeth__2.stl"/>
      </geometry>
    </collision>
    <!-- Part manifold_solid_brep_39_1_2 -->
    <visual>
      <origin xyz="-0.003 0 -0.0755" rpy="-3.14159 0 0"/>
      <geometry>
        <mesh filename="package://el_a3_description/meshes/manifold_solid_brep_39_1__2.stl"/>
      </geometry>
      <material name="yellow"/>
    </visual>
    <collision>
      <origin xyz="-0.003 0 -0.0755" rpy="-3.14159 0 0"/>
      <geometry>
        <mesh filename="package://el_a3_description/meshes/manifold_solid_brep_39_1__2.stl"/>
      </geometry>
    </collision>
    <!-- Part rack_base -->
    <visual>
      <origin xyz="0 0 -0.0755" rpy="-3.14159 0 0"/>
      <geometry>
        <mesh filename="package://el_a3_description/meshes/rack_base.stl"/>
      </geometry>
      <material name="light_blue"/>
    </visual>
    <collision>
      <origin xyz="0 0 -0.0755" rpy="-3.14159 0 0"/>
      <geometry>
        <mesh filename="package://el_a3_description/meshes/rack_base.stl"/>
      </geometry>
    </collision>
    <!-- Part rack_str -->
    <visual>
      <origin xyz="0 0 -0.0755" rpy="-3.14159 0 0"/>
      <geometry>
        <mesh filename="package://el_a3_description/meshes/rack_str.stl"/>
      </geometry>
      <material name="light_blue"/>
    </visual>
    <collision>
      <origin xyz="0 0 -0.0755" rpy="-3.14159 0 0"/>
      <geometry>
        <mesh filename="package://el_a3_description/meshes/rack_str.stl"/>
      </geometry>
    </collision>
    <!-- Part part_3 -->
    <visual>
      <origin xyz="0 0 -0.062" rpy="3.14159 -1.5708 0"/>
      <geometry>
        <mesh filename="package://el_a3_description/meshes/part_3.stl"/>
      </geometry>
      <material name="light_blue"/>
    </visual>
    <collision>
      <origin xyz="0 0 -0.062" rpy="3.14159 -1.5708 0"/>
      <geometry>
        <mesh filename="package://el_a3_description/meshes/part_3.stl"/>
      </geometry>
    </collision>
    <!-- Part el05_2 -->
    <visual>
      <origin xyz="0 0 -0.0305" rpy="0 0 0"/>
      <geometry>
        <mesh filename="package://el_a3_description/meshes/el05.stl"/>
      </geometry>
      <material name="white"/>
    </visual>
    <collision>
      <origin xyz="0 0 -0.0305" rpy="0 0 0"/>
      <geometry>
        <mesh filename="package://el_a3_description/meshes/el05.stl"/>
      </geometry>
    </collision>
    <!-- Part spur_gear__14_teeth -->
    <visual>
      <origin xyz="0 0 -0.0755" rpy="-3.14159 0 0"/>
      <geometry>
        <mesh filename="package://el_a3_description/meshes/spur_gear__14_teeth.stl"/>
      </geometry>
      <material name="white"/>
    </visual>
    <collision>
      <origin xyz="0 0 -0.0755" rpy="-3.14159 0 0"/>
      <geometry>
        <mesh filename="package://el_a3_description/meshes/spur_gear__14_teeth.stl"/>
      </geometry>
    </collision>
    <!-- Part part_15 -->
    <visual>
      <origin xyz="0 0 -0.0755" rpy="-3.14159 0 0"/>
      <geometry>
        <mesh filename="package://el_a3_description/meshes/part_15.stl"/>
      </geometry>
      <material name="blue"/>
    </visual>
    <collision>
      <origin xyz="0 0 -0.0755" rpy="-3.14159 0 0"/>
      <geometry>
        <mesh filename="package://el_a3_description/meshes/part_15.stl"/>
      </geometry>
    </collision>
    <!-- Part manifold_solid_brep_40_1 -->
    <visual>
      <origin xyz="0 0 -0.0755" rpy="-3.14159 0 0"/>
      <geometry>
        <mesh filename="package://el_a3_description/meshes/manifold_solid_brep_40_1.stl"/>
      </geometry>
      <material name="gray"/>
    </visual>
    <collision>
      <origin xyz="0 0 -0.0755" rpy="-3.14159 0 0"/>
      <geometry>
        <mesh filename="package://el_a3_description/meshes/manifold_solid_brep_40_1.stl"/>
      </geometry>
    </collision>
  </link>

  <!-- End Effector link -->
  <link name="end_effector"/>

  <!-- Joints -->
  <!-- Joint L1 (RS00 Motor 1) -->
  <joint name="L1_joint" type="revolute">
    <origin xyz="0 0 0.006" rpy="0 0 0"/>
    <parent link="l1_urdf_urdf_asm"/>
    <child link="l1_link_urdf_asm"/>
    <axis xyz="0 0 1"/>
    <limit effort="14" velocity="33" lower="-2.79253" upper="2.79253"/>
    <dynamics damping="0.1" friction="0.1"/>
  </joint>

  <!-- Joint L2 (RS00 Motor 2) -->
  <joint name="L2_joint" type="revolute">
    <origin xyz="-0.01 -0.0006 0.064" rpy="1.5708 0 0"/>
    <parent link="l1_link_urdf_asm"/>
    <child link="l2_l3_urdf_asm"/>
    <axis xyz="0 0 1"/>
    <limit effort="14" velocity="33" lower="0" upper="3.66519"/>
    <dynamics damping="0.1" friction="0.1"/>
  </joint>

  <!-- Joint L3 (RS00 Motor 3) -->
  <joint name="L3_joint" type="revolute">
    <origin xyz="0.19 0 0.0518" rpy="0 0 0"/>
    <parent link="l2_l3_urdf_asm"/>
    <child link="l3_lnik_urdf_asm"/>
    <axis xyz="0 0 1"/>
    <limit effort="14" velocity="33" lower="-4.01426" upper="0"/>
    <dynamics damping="0.1" friction="0.1"/>
  </joint>

  <!-- Joint L4 (EL05 Motor 4) -->
  <joint name="L4_joint" type="revolute">
    <origin xyz="-0.185 0.064 -0.0518" rpy="0 0 0"/>
    <parent link="l3_lnik_urdf_asm"/>
    <child link="l4_l5_urdf_asm"/>
    <axis xyz="0 0 1"/>
    <limit effort="6.0" velocity="50" lower="-1.5708" upper="1.5708"/>
    <dynamics damping="0.05" friction="0.05"/>
  </joint>

  <!-- Joint L5 (EL05 Motor 5) -->
  <joint name="L5_joint" type="revolute">
    <origin xyz="-0.0492 0.038 0" rpy="1.5708 0 0"/>
    <parent link="l4_l5_urdf_asm"/>
    <child link="part_9"/>
    <axis xyz="0 0 1"/>
    <limit effort="6.0" velocity="50" lower="-1.5708" upper="1.5708"/>
    <dynamics damping="0.05" friction="0.05"/>
  </joint>

  <!-- Joint L6 (EL05 Motor 6) -->
  <joint name="L6_joint" type="revolute">
    <origin xyz="0.00805 0 0.038" rpy="-1.5708 0 -1.5708"/>
    <parent link="part_9"/>
    <child link="l5_l6_urdf_asm"/>
    <axis xyz="0 0 1"/>
    <limit effort="6.0" velocity="50" lower="-1.5708" upper="1.5708"/>
    <dynamics damping="0.05" friction="0.05"/>
  </joint>

  <!-- End Effector joint -->
  <joint name="end_effector_joint" type="fixed">
    <origin xyz="0 0 -0.074" rpy="0 0 0"/>
    <parent link="l5_l6_urdf_asm"/>
    <child link="end_effector"/>
  </joint>

  <!-- ros2_control interface -->
  <xacro:el_a3_ros2_control 
    use_mock_hardware="$(arg use_mock_hardware)"
    can_interface="$(arg can_interface)"
    host_can_id="$(arg host_can_id)"/>

</robot>
